Workbook

Sheet Summary
B2: Key figures | C2: Actual | F2: Forecast
C3: 2023 | D3: 2024 | E3: 2025 | F3: 2026 | G3: 2027 | H3: 2028 | I3: 2029 | J3: 2030
B4: Revenue | C4: ='Income Statement'!C5 -> 5970146 | D4: ='Income Statement'!D5 -> 6676668 | E4: ='Income Statement'!E5 -> 7145768 | F4: ='Income Statement'!F5 -> 7600000 | G4: ='Income Statement'!G5 -> 7928131.1 | H4: ='Income Statement'!H5 -> 8270429.3 | I4: ='Income Statement'!I5 -> 8627506.2 | J4: ='Income Statement'!J5 -> 9000000
B5: Revenue growth % | C5: =Assumptions!C5 -> 0.17170724 | D5: =Assumptions!D5 -> 0.1183425 | E5: =Assumptions!E5 -> 0.070259597 | F5: =Assumptions!F5 -> 0.063566575 | G5: =Assumptions!G5 -> 0.043175141 | H5: =Assumptions!H5 -> 0.043175141 | I5: =Assumptions!I5 -> 0.043175141 | J5: =Assumptions!J5 -> 0.043175141
B6: EBIT | C6: ='Income Statement'!C11 -> 1617369 | D6: ='Income Statement'!D11 -> 1887751 | E6: ='Income Statement'!E11 -> 2109716 | F6: ='Income Statement'!F11 -> 2254605.6 | G6: ='Income Statement'!G11 -> 2351405.7 | H6: ='Income Statement'!H11 -> 2452385.2 | I6: ='Income Statement'!I11 -> 2557724.5 | J6: ='Income Statement'!J11 -> 2667611.8
B7: EBIT margin % | C7: =C6/C4 -> 0.27090946 | D7: =D6/D4 -> 0.28273849 | E7: =E6/E4 -> 0.29523992 | F7: =F6/F4 -> 0.29665863 | G7: =G6/G4 -> 0.29659017 | H7: =H6/H4 -> 0.29652453 | I7: =I6/I4 -> 0.29646162 | J7: =J6/J4 -> 0.29640131
B8: Net profit (owners) | C8: ='Income Statement'!C19 -> 1252048 | D8: ='Income Statement'!D19 -> 1521877 | E8: ='Income Statement'!E19 -> 1596919 | F8: ='Income Statement'!F19 -> 1708524.5 | G8: ='Income Statement'!G19 -> 1792367.3 | H8: ='Income Statement'!H19 -> 1880968.2 | I8: ='Income Statement'!I19 -> 1976279.1 | J8: ='Income Statement'!J19 -> 2078682.2
B9: Diluted EPS (€) | C9: ='Income Statement'!C23 -> 6.897918 | D9: ='Income Statement'!D23 -> 8.455248 | E9: ='Income Statement'!E23 -> 8.9553053 | F9: ='Income Statement'!F23 -> 9.6681077 | G9: ='Income Statement'!G23 -> 10.23458 | H9: ='Income Statement'!H23 -> 10.83795 | I9: ='Income Statement'!I23 -> 11.490439 | J9: ='Income Statement'!J23 -> 12.195485
B10: Cash | C10: ='Balance Sheet'!C18 -> 1121981 | D10: ='Balance Sheet'!D18 -> 1742214 | E10: ='Balance Sheet'!E18 -> 1467711 | F10: ='Balance Sheet'!F18 -> 1613413.4 | G10: ='Balance Sheet'!G18 -> 1828278 | H10: ='Balance Sheet'!H18 -> 2128381.5 | I10: ='Balance Sheet'!I18 -> 2519838.2 | J10: ='Balance Sheet'!J18 -> 3008420.5
B11: Debt | C11: ='Balance Sheet'!C30 -> 2477186 | D11: ='Balance Sheet'!D30 -> 3351888 | E11: ='Balance Sheet'!E30 -> 2884220 | F11: ='Balance Sheet'!F30 -> 2884220 | G11: ='Balance Sheet'!G30 -> 2884220 | H11: ='Balance Sheet'!H30 -> 2884220 | I11: ='Balance Sheet'!I30 -> 2884220 | J11: ='Balance Sheet'!J30 -> 2884220
B12: Net debt | C12: =C11-C10 -> 1355205 | D12: =D11-D10 -> 1609674 | E12: =E11-E10 -> 1416509 | F12: =F11-F10 -> 1270806.6 | G12: =G11-G10 -> 1055942 | H12: =H11-H10 -> 755838.53 | I12: =I11-I10 -> 364381.79 | J12: =J11-J10 -> -124200.47
B13: Free cash flow | C13: ='Cash Flow Statement'!C29+'Cash Flow Statement'!C22 -> 850185 | D13: ='Cash Flow Statement'!D29+'Cash Flow Statement'!D22 -> 939546 | E13: ='Cash Flow Statement'!E29+'Cash Flow Statement'!E22 -> 1405167 | F13: ='Cash Flow Statement'!F29+'Cash Flow Statement'!F22 -> 1484470 | G13: ='Cash Flow Statement'!G29+'Cash Flow Statement'!G22 -> 1598274.3 | H13: ='Cash Flow Statement'!H29+'Cash Flow Statement'!H22 -> 1717050.4 | I13: ='Cash Flow Statement'!I29+'Cash Flow Statement'!I22 -> 1843844 | J13: ='Cash Flow Statement'!J29+'Cash Flow Statement'!J22 -> 1979093.9
B15: Model integrity: Balance check: | C15: =IF(SUMPRODUCT(ABS('Balance Sheet'!C39:J39))<1,"OK","Error") -> OK
B17: Key assumptions
B18: Cost of sales as % of revenue | C18: =Assumptions!C7 -> 0.50180967 | D18: =Assumptions!D7 -> 0.49867434 | E18: =Assumptions!E7 -> 0.48321902 | F18: =Assumptions!F7 -> 0.48321902 | G18: =Assumptions!G7 -> 0.48321902 | H18: =Assumptions!H7 -> 0.48321902 | I18: =Assumptions!I7 -> 0.48321902 | J18: =Assumptions!J7 -> 0.48321902
B19: CapEx as % of revenue | C19: =Assumptions!C33 -> 0.1455425 | D19: =Assumptions!D33 -> 0.14815039 | E19: =Assumptions!E33 -> 0.13199225 | F19: =Assumptions!F33 -> 0.11578947 | G19: =Assumptions!G33 -> 0.11099716 | H19: =Assumptions!H33 -> 0.10640318 | I19: =Assumptions!I33 -> 0.10199935 | J19: =Assumptions!J33 -> 0.097777778
B20: Inventory days | C20: =Assumptions!C22 -> 115.56136 | D20: =Assumptions!D22 -> 119.29504 | E20: =Assumptions!E22 -> 117.74642 | F20: =Assumptions!F22 -> 117.53427 | G20: =Assumptions!G22 -> 117.53427 | H20: =Assumptions!H22 -> 117.53427 | I20: =Assumptions!I22 -> 117.53427 | J20: =Assumptions!J22 -> 117.53427
B21: Tax rate | C21: =Assumptions!C12 -> 0.21524395 | D21: =Assumptions!D12 -> 0.19219241 | E21: =Assumptions!E12 -> 0.22490363 | F21: =Assumptions!F12 -> 0.23 | G21: =Assumptions!G12 -> 0.23 | H21: =Assumptions!H12 -> 0.23 | I21: =Assumptions!I12 -> 0.23 | J21: =Assumptions!J12 -> 0.23
B22: Dividend payout ratio | D22: =Assumptions!D57 -> 0.35135873 | E22: =Assumptions!E57 -> 0.34806164 | F22: =Assumptions!F57 -> 0.4 | G22: =Assumptions!G57 -> 0.4 | H22: =Assumptions!H57 -> 0.4 | I22: =Assumptions!I57 -> 0.4 | J22: =Assumptions!J57 -> 0.4
B23: Share buybacks | C23: =Assumptions!C58 -> 460629 | D23: =Assumptions!D58 -> 581084 | E23: =Assumptions!E58 -> 785329 | F23: =Assumptions!F58 -> 700000 | G23: =Assumptions!G58 -> 700000 | H23: =Assumptions!H58 -> 700000 | I23: =Assumptions!I58 -> 700000 | J23: =Assumptions!J58 -> 700000

Sheet Assumptions
A3: Income Statement Assumptions | B3: 2022 | C3: 2023 | D3: 2024 | E3: 2025 | F3: 2026 | G3: 2027 | H3: 2028 | I3: 2029 | J3: 2030 | K3: Source/Rationale
A4: Revenue | B4: 5095254 | C4: ='Income Statement'!C5 -> 5970146 | D4: ='Income Statement'!D5 -> 6676668 | E4: ='Income Statement'!E5 -> 7145768 | F4: 7600000 | G4: =F4*(1+G5) -> 7928131.1 | H4: =G4*(1+H5) -> 8270429.3 | I4: =H4*(1+I5) -> 8627506.2 | J4: 9000000 | K4: 2026: revised guidance of about €7.6bn (Q2 2026 results). 2030: target of about €9.0bn (Capital Markets Day, Oct 2025). 2027 to 2029: constant growth that reaches the target
A5: Revenue Growth | C5: =(C4-B4)/B4 -> 0.17170724 | D5: =(D4-C4)/C4 -> 0.1183425 | E5: =(E4-D4)/D4 -> 0.070259597 | F5: =(F4-E4)/E4 -> 0.063566575 | G5: =(J4/F4)^(1/4) -1 -> 0.043175141 | H5: =G5 -> 0.043175141 | I5: =H5 -> 0.043175141 | J5: =I5 -> 0.043175141
A6: Cost of sales | C6: ='Income Statement'!C6 -> 2995877 | D6: ='Income Statement'!D6 -> 3329483 | E6: ='Income Statement'!E6 -> 3452971 | F6: =F4*F7 -> 3672464.5 | G6: =G4*G7 -> 3831023.7 | H6: =H4*H7 -> 3996428.7 | I6: =I4*I7 -> 4168975.1 | J6: =J4*J7 -> 4348971.2 | K6: Cost of sales in % of revenue * revenue
A7: Cost of sales in % of revenue | C7: ='Income Statement'!C6/Assumptions!C4 -> 0.50180967 | D7: ='Income Statement'!D6/Assumptions!D4 -> 0.49867434 | E7: ='Income Statement'!E6/Assumptions!E4 -> 0.48321902 | F7: =E7 -> 0.48321902 | G7: =F7 -> 0.48321902 | H7: =G7 -> 0.48321902 | I7: =H7 -> 0.48321902 | J7: =I7 -> 0.48321902 | K7: Held at 2025 level (48.3%). Falling trend but no company target. Resulting EBIT margin checked against guidance of at least 29.5% for 2026 and at least 30% for 2030.
A8: SG&A in % of revenue | C8: ='Income Statement'!C7/Assumptions!C4 -> 0.077482192 | D8: ='Income Statement'!D7/Assumptions!D4 -> 0.084045515 | E8: ='Income Statement'!E7/Assumptions!E4 -> 0.089911959 | F8: =E8 -> 0.089911959 | G8: =F8 -> 0.089911959 | H8: =G8 -> 0.089911959 | I8: =H8 -> 0.089911959 | J8: =I8 -> 0.089911959 | K8: Held at 2025 level (9.0%). Rising trend. The 2026 outlook cites higher brand investments (2025 annual report p.122) but gives no figure.
A9: R&D in % of revenue | C9: ='Income Statement'!C8/Assumptions!C4 -> 0.14766121 | D9: ='Income Statement'!D8/Assumptions!D4 -> 0.1339129 | E9: ='Income Statement'!E8/Assumptions!E4 -> 0.12858814 | F9: =E9 -> 0.12858814 | G9: =F9 -> 0.12858814 | H9: =G9 -> 0.12858814 | I9: =H9 -> 0.12858814 | J9: =I9 -> 0.12858814 | K9: Held at 2025 level (12.9%). Falling trend, no company target. The outlook cites higher racing and digital expenses
A10: Other expenses, net in % of revenue | C10: ='Income Statement'!C9/Assumptions!C4 -> 0.0031654167 | D10: ='Income Statement'!D9/Assumptions!D4 -> 0.0018636541 | E10: ='Income Statement'!E9/Assumptions!E4 -> 0.0048003238 | F10: =AVERAGE($C10:$E10) -> 0.0032764649 | G10: =AVERAGE($C10:$E10) -> 0.0032764649 | H10: =AVERAGE($C10:$E10) -> 0.0032764649 | I10: =AVERAGE($C10:$E10) -> 0.0032764649 | J10: =AVERAGE($C10:$E10) -> 0.0032764649 | K10: Values are volatile and small, forecasts will then use the average of the historical values
A11: Implied EBIT margin | C11: =100%-(SUM(C7:C10))+C16/C4 -> 0.27090946 | D11: =100%-(SUM(D7:D10))+D16/D4 -> 0.28273849 | E11: =100%-(SUM(E7:E10))+E16/E4 -> 0.29523992 | F11: =100%-(SUM(F7:F10))+F16/F4 -> 0.29665863 | G11: =100%-(SUM(G7:G10))+G16/G4 -> 0.29659017 | H11: =100%-(SUM(H7:H10))+H16/H4 -> 0.29652453 | I11: =100%-(SUM(I7:I10))+I16/I4 -> 0.29646162 | J11: =100%-(SUM(J7:J10))+J16/J4 -> 0.29640131
A12: Effective tax rate (income tax/profit before tax) | C12: ='Income Statement'!C16/'Income Statement'!C15 -> 0.21524395 | D12: ='Income Statement'!D16/'Income Statement'!D15 -> 0.19219241 | E12: ='Income Statement'!E16/'Income Statement'!E15 -> 0.22490363 | F12: 0.23 | G12: 0.23 | H12: 0.23 | I12: 0.23 | J12: 0.23 | K12: 23%: H1 2026 effective rate under the new Patent Box regime (Q2 2026 results). 2023 and 2024 were lowered by two overlapping regimes, so the average would understate
A13: Non-controlling interests % of net profit | C13: ='Income Statement'!C20/'Income Statement'!C17 -> 0.0043015387 | D13: ='Income Statement'!D20/'Income Statement'!D17 -> 0.0026449739 | E13: ='Income Statement'!E20/'Income Statement'!E17 -> 0.0016236161 | F13: =E13 -> 0.0016236161 | G13: =F13 -> 0.0016236161 | H13: =G13 -> 0.0016236161 | I13: =H13 -> 0.0016236161 | J13: =I13 -> 0.0016236161 | K13: Held at 2025 level (0.16%). Small and declining, immaterial to net profit
A14: Interest rate on debt | D14: ='Income Statement'!D13/'Balance Sheet'!C30 -> 0.058895456 | E14: ='Income Statement'!E13/'Balance Sheet'!D30 -> 0.06391204 | F14: =E14 -> 0.06391204 | G14: =F14 -> 0.06391204 | H14: =G14 -> 0.06391204 | I14: =H14 -> 0.06391204 | J14: =I14 -> 0.06391204 | K14: Financial expenses ÷ previous year-end total debt - This and the next row will start at 2024 because no 2022 data - Held at 2025 level (6.39%). Applied to previous year-end debt to avoid a circular reference
A15: Yield on cash and financing receivables | D15: ='Income Statement'!D12/('Balance Sheet'!C14+'Balance Sheet'!C18) -> 0.05716753 | E15: ='Income Statement'!E12/('Balance Sheet'!D14+'Balance Sheet'!D18) -> 0.049398533 | F15: =E15 -> 0.049398533 | G15: =F15 -> 0.049398533 | H15: =G15 -> 0.049398533 | I15: =H15 -> 0.049398533 | J15: =I15 -> 0.049398533 | K15: Financial income ÷ previous year-end (cash + receivables from financing activities) - Held at 2025 level (4.94%). Falling trend. Applied to previous year-end cash plus financing receivables
A16: Result from investments | C16: ='Income Statement'!C10 -> 6137 | D16: ='Income Statement'!D10 -> 8245 | E16: ='Income Statement'!E10 -> 12572 | F16: =E16 -> 12572 | G16: =F16 -> 12572 | H16: =G16 -> 12572 | I16: =H16 -> 12572 | J16: =I16 -> 12572 | K16: Extracted from IS | Values are rising - Held flat at 2025 amount because no company guidance
A20: Balance Sheet Assumptions (and some cash flow info)
A21: Working Capital: | K21: Interpretation: At the end of 2025, Ferrari holds about 118 days’ worth of production costs in inventory - Stable values, average for forecasted years
A22: Inventories (days worth) | C22: ='Balance Sheet'!C12/Assumptions!C6*365 -> 115.56136 | D22: ='Balance Sheet'!D12/Assumptions!D6*365 -> 119.29504 | E22: ='Balance Sheet'!E12/Assumptions!E6*365 -> 117.74642 | F22: =AVERAGE($C22:$E22) -> 117.53427 | G22: =AVERAGE($C22:$E22) -> 117.53427 | H22: =AVERAGE($C22:$E22) -> 117.53427 | I22: =AVERAGE($C22:$E22) -> 117.53427 | J22: =AVERAGE($C22:$E22) -> 117.53427 | K22: Average of 2023 to 2025. Stable (about 116 to 119 days for inventories, and 16 to 19 days for receivables)
A23: Inventories (in 1000 Euros) | C23: =C22*C6/365 -> 948514 | D23: =D22*D6/365 -> 1088194 | E23: =E22*E6/365 -> 1113904 | F23: =F22*F6/365 -> 1182576.6 | G23: =G22*G6/365 -> 1233634.5 | H23: =H22*H6/365 -> 1286896.8 | I23: =I22*I6/365 -> 1342458.8 | J23: =J22*J6/365 -> 1400419.6
A24: Trade receivables (days worth) | C24: ='Balance Sheet'!C13/Assumptions!C4*365 -> 15.980128 | D24: ='Balance Sheet'!D13/Assumptions!D4*365 -> 19.088749 | E24: ='Balance Sheet'!E13/Assumptions!E4*365 -> 18.405822 | F24: =AVERAGE($C24:$E24) -> 17.8249 | G24: =AVERAGE($C24:$E24) -> 17.8249 | H24: =AVERAGE($C24:$E24) -> 17.8249 | I24: =AVERAGE($C24:$E24) -> 17.8249 | J24: =AVERAGE($C24:$E24) -> 17.8249
A25: Trade receivables (in 1000 euros) | C25: =C24*C4/365 -> 261380 | D25: =D24*D4/365 -> 349176 | E25: =E24*E4/365 -> 360339 | F25: =F24*F4/365 -> 371148.6 | G25: =G24*G4/365 -> 387172.99 | H25: =H24*H4/365 -> 403889.24 | I25: =I24*I4/365 -> 421327.22 | J25: =J24*J4/365 -> 439518.08
A26: Trade (days worth) | C26: ='Balance Sheet'!C33/Assumptions!C6*365 -> 113.37395 | D26: ='Balance Sheet'!D33/Assumptions!D6*365 -> 103.66919 | E26: ='Balance Sheet'!E33/Assumptions!E6*365 -> 88.925867 | F26: =E26 -> 88.925867 | G26: =F26 -> 88.925867 | H26: =G26 -> 88.925867 | I26: =H26 -> 88.925867 | J26: =I26 -> 88.925867 | K26: Held at 2025 level (89 days). The fall from 113 to 104 to 89 is not extrapolated, and the company gives no information.
A27: Trade Payables (in 1000 euros) | C27: =C26*C6/365 -> 930560 | D27: =D26*D6/365 -> 945657 | E27: =E26*E6/365 -> 841256 | F27: =F26*F6/365 -> 894731.76 | G27: =G26*G6/365 -> 933361.93 | H27: =H26*H6/365 -> 973659.97 | I27: =I26*I6/365 -> 1015697.9 | J27: =J26*J6/365 -> 1059550.8
A28: Receivables from financing activities (Ferrari-specific) as % of revenue | C28: ='Balance Sheet'!C14/Assumptions!C4 -> 0.2430691 | D28: ='Balance Sheet'!D14/Assumptions!D4 -> 0.24887144 | E28: ='Balance Sheet'!E14/Assumptions!E4 -> 0.22578343 | F28: =E28 -> 0.22578343 | G28: =F28 -> 0.22578343 | H28: =G28 -> 0.22578343 | I28: =H28 -> 0.22578343 | J28: =I28 -> 0.22578343 | K28: Ferrari’s customer-financing book, so it is a simplification - Latest value will be held to avoid a jump in 2026
A29: Total CapEx from 2026 to 2030 | F29: 4400000 | K29: Company plan of about €4.7bn (Capital Markets Day), converted to cash capex at about 93% (2025 cash capex ÷ company capex) = about €4.4bn.
A30: Property, Plant & Equipment and Intangible Assets
A31: Capital Expanditures (CapEx) | C31: =-SUM('Cash Flow Statement'!C25:C26) -> 868910 | D31: =-SUM('Cash Flow Statement'!D25:D26) -> 989151 | E31: =-SUM('Cash Flow Statement'!E25:E26) -> 943186 | F31: =$F29/5 -> 880000 | G31: =$F29/5 -> 880000 | H31: =$F29/5 -> 880000 | I31: =$F29/5 -> 880000 | J31: =$F29/5 -> 880000 | K31: 4.4bn spread over the 5 forecasted years
A32: Depreciation & Amortization | C32: ='PPE and Intangible'!B14 -> 662305 | D32: ='PPE and Intangible'!C14 -> 666777 | E32: ='PPE and Intangible'!D14 -> 661936 | F32: =F36*F4 -> 710600 | G32: =G36*G4 -> 741280.26 | H32: =H36*H4 -> 773285.13 | I32: =I36*I4 -> 806671.83 | J32: =J36*J4 -> 841500 | K32: For the forecasts, simply D%A%*revenue
A33: CapEx as a % of revenue | C33: =C31/C4 -> 0.1455425 | D33: =D31/D4 -> 0.14815039 | E33: =E31/E4 -> 0.13199225 | F33: =F31/F4 -> 0.11578947 | G33: =G31/G4 -> 0.11099716 | H33: =H31/H4 -> 0.10640318 | I33: =I31/I4 -> 0.10199935 | J33: =J31/J4 -> 0.097777778
A34: Intangibles' share of CapEx | C34: =-'Cash Flow Statement'!C25/Assumptions!C31 -> 0.56064264 | D34: =-'Cash Flow Statement'!D25/Assumptions!D31 -> 0.51243339 | E34: =-'Cash Flow Statement'!E25/Assumptions!E31 -> 0.48556276 | F34: =E34 -> 0.48556276 | G34: =F34 -> 0.48556276 | H34: =G34 -> 0.48556276 | I34: =H34 -> 0.48556276 | J34: =I34 -> 0.48556276 | K34: Forecasts will be held flat at the 2025 value
A35: PPE's share of CapEx | C35: =100%-C34 -> 0.43935736 | D35: =100%-D34 -> 0.48756661 | E35: =100%-E34 -> 0.51443724 | F35: =100%-F34 -> 0.51443724 | G35: =100%-G34 -> 0.51443724 | H35: =100%-H34 -> 0.51443724 | I35: =100%-I34 -> 0.51443724 | J35: =100%-J34 -> 0.51443724
A36: D&A as a % of revenue | C36: =C32/C4 -> 0.11093615 | D36: =D32/D4 -> 0.09986673 | E36: =E32/E4 -> 0.09263329 | F36: 0.0935 | G36: 0.0935 | H36: 0.0935 | I36: 0.0935 | J36: 0.0935 | K36: 9.35% of revenue. Guidance (EBITDA minus EBIT) implies about €0.71bn in 2026 and about €0.85bn in 2030, i.e. 9.3 to 9.4%. Simplified: real D&A depends on the asset base
A37: Intangibles' share of D&A | C37: ='PPE and Intangible'!B6/Assumptions!C32 -> 0.56182725 | D37: ='PPE and Intangible'!C6/Assumptions!D32 -> 0.55061737 | E37: ='PPE and Intangible'!D6/Assumptions!E32 -> 0.54869655 | F37: =E37 -> 0.54869655 | G37: =F37 -> 0.54869655 | H37: =G37 -> 0.54869655 | I37: =H37 -> 0.54869655 | J37: =I37 -> 0.54869655 | K37: Forecasts will be held flat at the 2025 value
A38: PPE's share of D&A | C38: =1-C37 -> 0.43817275 | D38: =1-D37 -> 0.44938263 | E38: =1-E37 -> 0.45130345 | F38: =1-F37 -> 0.45130345 | G38: =1-G37 -> 0.45130345 | H38: =1-H37 -> 0.45130345 | I38: =1-I37 -> 0.45130345 | J38: =1-J37 -> 0.45130345
A39: Debt
A40: Repayments | C40: =-('Cash Flow Statement'!C32+'Cash Flow Statement'!C34+'Cash Flow Statement'!C36+'Cash Flow Statement'!C38+'Cash Flow Statement'!C40) -> 751070 | D40: =-('Cash Flow Statement'!D32+'Cash Flow Statement'!D34+'Cash Flow Statement'!D36+'Cash Flow Statement'!D38+'Cash Flow Statement'!D40) -> 411637 | E40: =-('Cash Flow Statement'!E32+'Cash Flow Statement'!E34+'Cash Flow Statement'!E36+'Cash Flow Statement'!E38+'Cash Flow Statement'!E40) -> 932575 | F40: =E54 -> 962309 | G40: =G41*'Balance Sheet'!F30 -> 802458.63 | H40: =H41*'Balance Sheet'!G30 -> 802458.63 | I40: =I41*'Balance Sheet'!H30 -> 802458.63 | J40: =J41*'Balance Sheet'!I30 -> 802458.63 | K40: 2026: current portion of debt at end 2025 (€962m, debt note).
A41: Repayments as a % of opening debt | D41: =D40/'Balance Sheet'!C30 -> 0.16617121 | E41: =E40/'Balance Sheet'!D30 -> 0.2782238 | F41: =F40/'Balance Sheet'!E30 -> 0.33364619 | G41: =E41 -> 0.2782238 | H41: =G41 -> 0.2782238 | I41: =H41 -> 0.2782238 | J41: =I41 -> 0.2782238 | K41: 2027 to 2030: 2025 ratio of repayments to opening debt (27.82%), applied to previous year-end debt
A42: Bonds share of repayments | C42: =-'Cash Flow Statement'!C32/Assumptions!C40 -> 0.76650911 | D42: =-'Cash Flow Statement'!D32/Assumptions!D40 -> 0 | E42: =-'Cash Flow Statement'!E32/Assumptions!E40 -> 0.48356754 | F42: =-SUM('Cash Flow Statement'!$C32:$E32)/SUM($C$40:$E$40) -> 0.48998894 | G42: =-SUM('Cash Flow Statement'!$C32:$E32)/SUM($C$40:$E$40) -> 0.48998894 | H42: =-SUM('Cash Flow Statement'!$C32:$E32)/SUM($C$40:$E$40) -> 0.48998894 | I42: =-SUM('Cash Flow Statement'!$C32:$E32)/SUM($C$40:$E$40) -> 0.48998894 | J42: =-SUM('Cash Flow Statement'!$C32:$E32)/SUM($C$40:$E$40) -> 0.48998894 | K42: Pooled 2023 to 2025: each line’s total repayments ÷ total repayments over the three years. Debt flows are lumpy (e.g. in 2025 bonds were 48% of repayments), so one year is not representative. The split only affects how the cash flow statement is presented. The total comes from the repayment assumption above, so it does not change the balance sheet.
A43: Securization shares of repayments | C43: =-'Cash Flow Statement'!C34/Assumptions!C40 -> 0.066053763 | D43: =-'Cash Flow Statement'!D34/Assumptions!D40 -> 0.59190257 | E43: =-'Cash Flow Statement'!E34/Assumptions!E40 -> 0.03570115 | F43: =-SUM('Cash Flow Statement'!$C34:$E34)/SUM($C$40:$E$40) -> 0.15585205 | G43: =-SUM('Cash Flow Statement'!$C34:$E34)/SUM($C$40:$E$40) -> 0.15585205 | H43: =-SUM('Cash Flow Statement'!$C34:$E34)/SUM($C$40:$E$40) -> 0.15585205 | I43: =-SUM('Cash Flow Statement'!$C34:$E34)/SUM($C$40:$E$40) -> 0.15585205 | J43: =-SUM('Cash Flow Statement'!$C34:$E34)/SUM($C$40:$E$40) -> 0.15585205
A44: Bank loans shares of repayments | C44: =-'Cash Flow Statement'!C36/Assumptions!C40 -> 0.096528952 | D44: =-'Cash Flow Statement'!D36/Assumptions!D40 -> 0.25432602 | E44: =-'Cash Flow Statement'!E36/Assumptions!E40 -> 0.40568533 | F44: =-SUM('Cash Flow Statement'!$C36:$E36)/SUM($C$40:$E$40) -> 0.26512994 | G44: =-SUM('Cash Flow Statement'!$C36:$E36)/SUM($C$40:$E$40) -> 0.26512994 | H44: =-SUM('Cash Flow Statement'!$C36:$E36)/SUM($C$40:$E$40) -> 0.26512994 | I44: =-SUM('Cash Flow Statement'!$C36:$E36)/SUM($C$40:$E$40) -> 0.26512994 | J44: =-SUM('Cash Flow Statement'!$C36:$E36)/SUM($C$40:$E$40) -> 0.26512994
A45: Other debt shares of repayments | C45: =-'Cash Flow Statement'!C38/Assumptions!C40 -> 0.047353775 | D45: =-'Cash Flow Statement'!D38/Assumptions!D40 -> 0.10032383 | E45: =-'Cash Flow Statement'!E38/Assumptions!E40 -> 0.049498432 | F45: =-SUM('Cash Flow Statement'!$C38:$E38)/SUM($C$40:$E$40) -> 0.05871477 | G45: =-SUM('Cash Flow Statement'!$C38:$E38)/SUM($C$40:$E$40) -> 0.05871477 | H45: =-SUM('Cash Flow Statement'!$C38:$E38)/SUM($C$40:$E$40) -> 0.05871477 | I45: =-SUM('Cash Flow Statement'!$C38:$E38)/SUM($C$40:$E$40) -> 0.05871477 | J45: =-SUM('Cash Flow Statement'!$C38:$E38)/SUM($C$40:$E$40) -> 0.05871477
...

Sheet Income Statement
A1: FERRARI N.V. CONSOLIDATED INCOME STATEMENT FOR THE YEARS ENDED DECEMBER 31, 2025, 2024 AND 2023
D2: For the years ended December 31, | F2: Forecasted years
B3: Note | C3: 2023 | D3: 2024 | E3: 2025 | F3: 2026 | G3: 2027 | H3: 2028 | I3: 2029 | J3: 2030
B4: (EUR thousand)
A5: Net revenues | B5: 4 | C5: 5970146 | D5: 6676668 | E5: 7145768 | F5: =Assumptions!F4 -> 7600000 | G5: =Assumptions!G4 -> 7928131.1 | H5: =Assumptions!H4 -> 8270429.3 | I5: =Assumptions!I4 -> 8627506.2 | J5: =Assumptions!J4 -> 9000000
A6: Cost of sales (cogs) | B6: 5 | C6: 2995877 | D6: 3329483 | E6: 3452971 | F6: =Assumptions!F6 -> 3672464.5 | G6: =Assumptions!G6 -> 3831023.7 | H6: =Assumptions!H6 -> 3996428.7 | I6: =Assumptions!I6 -> 4168975.1 | J6: =Assumptions!J6 -> 4348971.2
A7: Selling, general and administrative costs (sg&a) | B7: 6 | C7: 462580 | D7: 561144 | E7: 642490 | F7: =F5*Assumptions!F8 -> 683330.89 | G7: =G5*Assumptions!G8 -> 712833.8 | H7: =H5*Assumptions!H8 -> 743610.5 | I7: =I5*Assumptions!I8 -> 775715.98 | J7: =J5*Assumptions!J8 -> 809207.63
A8: Research and development costs | B8: 7 | C8: 881559 | D8: 894092 | E8: 918861 | F8: =F5*Assumptions!F9 -> 977269.85 | G8: =G5*Assumptions!G9 -> 1019463.6 | H8: =H5*Assumptions!H9 -> 1063479.1 | I8: =I5*Assumptions!I9 -> 1109395 | J8: =J5*Assumptions!J9 -> 1157293.2
A9: Other expenses, net | B9: 8 | C9: 18898 | D9: 12443 | E9: 34302 | F9: =F5*Assumptions!F10 -> 24901.133 | G9: =G5*Assumptions!G10 -> 25976.243 | H9: =H5*Assumptions!H10 -> 27097.771 | I9: =I5*Assumptions!I10 -> 28267.721 | J9: =J5*Assumptions!J10 -> 29488.184
A10: Result from investments | C10: 6137 | D10: 8245 | E10: 12572 | F10: =Assumptions!F16 -> 12572 | G10: =Assumptions!G16 -> 12572 | H10: =Assumptions!H16 -> 12572 | I10: =Assumptions!I16 -> 12572 | J10: =Assumptions!J16 -> 12572
A11: Operating profit (EBIT) | C11: =C5-C6-C7-C8-C9+C10 -> 1617369 | D11: =D5-D6-D7-D8-D9+D10 -> 1887751 | E11: =E5-E6-E7-E8-E9+E10 -> 2109716 | F11: =F5-F6-F7-F8-F9+F10 -> 2254605.6 | G11: =G5-G6-G7-G8-G9+G10 -> 2351405.7 | H11: =H5-H6-H7-H8-H9+H10 -> 2452385.2 | I11: =I5-I6-I7-I8-I9+I10 -> 2557724.5 | J11: =J5-J6-J7-J8-J9+J10 -> 2667611.8
A12: Financial income | B12: 9 | C12: 132319 | D12: 147100 | E12: 168145 | F12: =Assumptions!F15*('Balance Sheet'!E14+'Balance Sheet'!E18) -> 152202.17 | G12: =Assumptions!G15*('Balance Sheet'!F14+'Balance Sheet'!F18) -> 164465.87 | H12: =Assumptions!H15*('Balance Sheet'!G14+'Balance Sheet'!G18) -> 178739.63 | I12: =Assumptions!I15*('Balance Sheet'!H14+'Balance Sheet'!H18) -> 197382.08 | J12: =Assumptions!J15*('Balance Sheet'!I14+'Balance Sheet'!I18) -> 220702.08 | K12: Financial income and expenses will be filled after balance sheet
A13: Financial expenses | B13: 9 | C13: 147334 | D13: 145895 | E13: 214226 | F13: =Assumptions!F14*('Balance Sheet'!E30) -> 184336.38 | G13: =Assumptions!G14*('Balance Sheet'!F30) -> 184336.38 | H13: =Assumptions!H14*('Balance Sheet'!G30) -> 184336.38 | I13: =Assumptions!I14*('Balance Sheet'!H30) -> 184336.38 | J13: =Assumptions!J14*('Balance Sheet'!I30) -> 184336.38
A14: Financial expenses/(income), net | B14: 9 | C14: 15015 | D14: -1205 | E14: 46081 | F14: =F13-F12 -> 32134.217 | G14: =G13-G12 -> 19870.512 | H14: =H13-H12 -> 5596.7523 | I14: =I13-I12 -> -13045.698 | J14: =J13-J12 -> -36365.699
A15: Profit before taxes | C15: =C11-C13+C12 -> 1602354 | D15: =D11-D13+D12 -> 1888956 | E15: =E11-E13+E12 -> 2063635 | F15: =F11-F13+F12 -> 2222471.4 | G15: =G11-G13+G12 -> 2331535.2 | H15: =H11-H13+H12 -> 2446788.4 | I15: =I11-I13+I12 -> 2570770.2 | J15: =J11-J13+J12 -> 2703977.5
A16: Income tax expense | B16: 10 | C16: 344897 | D16: 363043 | E16: 464119 | F16: =F15*Assumptions!F12 -> 511168.42 | G16: =G15*Assumptions!G12 -> 536253.09 | H16: =H15*Assumptions!H12 -> 562761.34 | I16: =I15*Assumptions!I12 -> 591277.14 | J16: =J15*Assumptions!J12 -> 621914.82
A17: Net profit | C17: =C15-C16 -> 1257457 | D17: =D15-D16 -> 1525913 | E17: =E15-E16 -> 1599516 | F17: =F15-F16 -> 1711303 | G17: =G15-G16 -> 1795282.1 | H17: =H15-H16 -> 1884027.1 | I17: =I15-I16 -> 1979493 | J17: =J15-J16 -> 2082062.7
A18: Net profit attributable to:
A19: Owners o/ the parent | C19: 1252048 | D19: 1521877 | E19: 1596919 | F19: =F17-F20 -> 1708524.5 | G19: =G17-G20 -> 1792367.3 | H19: =H17-H20 -> 1880968.2 | I19: =I17-I20 -> 1976279.1 | J19: =J17-J20 -> 2078682.2
A20: Non-controlling interests | B20: 3 | C20: 5409 | D20: 4036 | E20: 2597 | F20: =F17*Assumptions!F13 -> 2778.4991 | G20: =G17*Assumptions!G13 -> 2914.849 | H20: =H17*Assumptions!H13 -> 3058.9368 | I20: =I17*Assumptions!I13 -> 3213.9368 | J20: =J17*Assumptions!J13 -> 3380.4705
A22: Basic earnings per common share (in €) | B22: 12 | C22: =EPS!B13 -> 6.9089946 | D22: =EPS!C13 -> 8.4669612 | E22: =EPS!D13 -> 8.9651593 | F22: =EPS!E13 -> 9.6788427 | G22: =EPS!F13 -> 10.246047 | H22: =EPS!G13 -> 10.850204 | I22: =EPS!H13 -> 11.503549 | J22: =EPS!I13 -> 12.209525
A23: Diluted earnings per common share (in €) | B23: 12 | C23: =EPS!B5 -> 6.897918 | D23: =EPS!C5 -> 8.455248 | E23: =EPS!D5 -> 8.9553053 | F23: =EPS!E5 -> 9.6681077 | G23: =EPS!F5 -> 10.23458 | H23: =EPS!G5 -> 10.83795 | I23: =EPS!H5 -> 11.490439 | J23: =EPS!I5 -> 12.195485

Sheet Balance Sheet
A1: FERRARI N.V. CONSOLIDATED STATEMENT OF FINANCIAL POSITION AT DECEMBER 31, 2025 AND 2024
B2: At December 31, | F2: Forecasted years
B3: Note | C3: 2023 | D3: 2024 | E3: 2025 | F3: 2026 | G3: 2027 | H3: 2028 | I3: 2029 | J3: 2030
B4: (EUR thousand)
A5: Assets
A6: Goodwill | B6: 13 | C6: 785182 | D6: 785182 | E6: 785182 | F6: =E6 -> 785182 | G6: =F6 -> 785182 | H6: =G6 -> 785182 | I6: =H6 -> 785182 | J6: =I6 -> 785182
A7: Intangible assets | B7: 14 | C7: 1419699 | D7: 1545664 | E7: 1638457 | F7: =E7+Assumptions!F31*Assumptions!F34-Assumptions!F32*Assumptions!F37 -> 1675848.5 | G7: =F7+Assumptions!G31*Assumptions!G34-Assumptions!G32*Assumptions!G37 -> 1696405.8 | H7: =G7+Assumptions!H31*Assumptions!H34-Assumptions!H32*Assumptions!H37 -> 1699402.1 | I7: =H7+Assumptions!I31*Assumptions!I34-Assumptions!I32*Assumptions!I37 -> 1684079.3 | J7: =I7+Assumptions!J31*Assumptions!J34-Assumptions!J32*Assumptions!J37 -> 1649646.4
A8: Property, plant and equipment | B8: 15 | C8: 1575200 | D8: 1828784 | E8: 2057891 | F8: =E8+Assumptions!F31*(Assumptions!F35)-Assumptions!F32*Assumptions!F38 -> 2189899.5 | G8: =F8+Assumptions!G31*(Assumptions!G35)-Assumptions!G32*Assumptions!G38 -> 2308062 | H8: =G8+Assumptions!H31*(Assumptions!H35)-Assumptions!H32*Assumptions!H38 -> 2411780.5 | I8: =H8+Assumptions!I31*(Assumptions!I35)-Assumptions!I32*Assumptions!I38 -> 2500431.5 | J8: =I8+Assumptions!J31*(Assumptions!J35)-Assumptions!J32*Assumptions!J38 -> 2573364.4
A9: Investments and other financial assets | B9: 16 | C9: 67671 | D9: 80822 | E9: 96444 | F9: =E9+'Income Statement'!F10 -> 109016 | G9: =F9+'Income Statement'!G10 -> 121588 | H9: =G9+'Income Statement'!H10 -> 134160 | I9: =H9+'Income Statement'!I10 -> 146732 | J9: =I9+'Income Statement'!J10 -> 159304
A10: Deferred tax assets | B10: 10 | C10: 217553 | D10: 236791 | E10: 226005 | F10: =E10 -> 226005 | G10: =F10 -> 226005 | H10: =G10 -> 226005 | I10: =H10 -> 226005 | J10: =I10 -> 226005
A11: Total non-current assets | C11: =SUM(C6:C10) -> 4065305 | D11: =SUM(D6:D10) -> 4477243 | E11: =SUM(E6:E10) -> 4803979 | F11: =SUM(F6:F10) -> 4985951 | G11: =SUM(G6:G10) -> 5137242.7 | H11: =SUM(H6:H10) -> 5256529.6 | I11: =SUM(I6:I10) -> 5342429.8 | J11: =SUM(J6:J10) -> 5393501.8
A12: Inventories | B12: 17 | C12: 948514 | D12: 1088194 | E12: 1113904 | F12: =Assumptions!F23 -> 1182576.6 | G12: =Assumptions!G23 -> 1233634.5 | H12: =Assumptions!H23 -> 1286896.8 | I12: =Assumptions!I23 -> 1342458.8 | J12: =Assumptions!J23 -> 1400419.6
A13: Trade receivables | B13: 18 | C13: 261380 | D13: 349176 | E13: 360339 | F13: =Assumptions!F25 -> 371148.6 | G13: =Assumptions!G25 -> 387172.99 | H13: =Assumptions!H25 -> 403889.24 | I13: =Assumptions!I25 -> 421327.22 | J13: =Assumptions!J25 -> 439518.08
A14: Receivables from financing activities | B14: 18 | C14: 1451158 | D14: 1661632 | E14: 1613396 | F14: =Assumptions!F28*Assumptions!F4 -> 1715954.1 | G14: =Assumptions!G28*Assumptions!G4 -> 1790040.6 | H14: =Assumptions!H28*Assumptions!H4 -> 1867325.9 | I14: =Assumptions!I28*Assumptions!I4 -> 1947947.9 | J14: =Assumptions!J28*Assumptions!J4 -> 2032050.9
A15: Tax receivables | B15: 18 | C15: 11616 | D15: 15918 | E15: 31715 | F15: =E15 -> 31715 | G15: =F15 -> 31715 | H15: =G15 -> 31715 | I15: =H15 -> 31715 | J15: =I15 -> 31715
A16: Other current assets | B16: 18 | C16: 130228 | D16: 137763 | E16: 159223 | F16: =Assumptions!F60*Assumptions!F4 -> 163979.72 | G16: =Assumptions!G60*Assumptions!G4 -> 171059.57 | H16: =Assumptions!H60*Assumptions!H4 -> 178445.09 | I16: =Assumptions!I60*Assumptions!I4 -> 186149.48 | J16: =Assumptions!J60*Assumptions!J4 -> 194186.51
A17: Current financial assets | B17: 19 | C17: 61130 | D17: 25006 | E17: 78085 | F17: =E17 -> 78085 | G17: =F17 -> 78085 | H17: =G17 -> 78085 | I17: =H17 -> 78085 | J17: =I17 -> 78085
A18: Cash and cash equivalents | B18: 32 | C18: 1121981 | D18: 1742214 | E18: 1467711 | F18: ='Cash Flow Statement'!F48 -> 1613413.4 | G18: ='Cash Flow Statement'!G48 -> 1828278 | H18: ='Cash Flow Statement'!H48 -> 2128381.5 | I18: ='Cash Flow Statement'!I48 -> 2519838.2 | J18: ='Cash Flow Statement'!J48 -> 3008420.5 | K18: cash completed after CF statement
A19: Total current assets | C19: =SUM(C12:C18) -> 3986007 | D19: =SUM(D12:D18) -> 5019903 | E19: =SUM(E12:E18) -> 4824373 | F19: =SUM(F12:F18) -> 5156872.4 | G19: =SUM(G12:G18) -> 5519985.6 | H19: =SUM(H12:H18) -> 5974738.5 | I19: =SUM(I12:I18) -> 6527521.6 | J19: =SUM(J12:J18) -> 7184395.5
A20: Total assets | C20: =C19+C11 -> 8051312 | D20: =D19+D11 -> 9497146 | E20: =E19+E11 -> 9628352 | F20: =F19+F11 -> 10142823 | G20: =G19+G11 -> 10657228 | H20: =H19+H11 -> 11231268 | I20: =I19+I11 -> 11869951 | J20: =J19+J11 -> 12577897
A22: Equity and liabilities
A23: Equity attributable to owners of the parent | C23: 3060888 | D23: 3533946 | E23: 3906893 | F23: =E23+'Income Statement'!F19-Assumptions!F58-Assumptions!F57*'Income Statement'!E19 -> 4276649.9 | G23: =F23+'Income Statement'!G19-Assumptions!G58-Assumptions!G57*'Income Statement'!F19 -> 4685607.3 | H23: =G23+'Income Statement'!H19-Assumptions!H58-Assumptions!H57*'Income Statement'!G19 -> 5149628.6 | I23: =H23+'Income Statement'!I19-Assumptions!I58-Assumptions!I57*'Income Statement'!H19 -> 5673520.4 | J23: =I23+'Income Statement'!J19-Assumptions!J58-Assumptions!J57*'Income Statement'!I19 -> 6261691
A24: Non-controlling interests | B24: 3 | C24: 9734 | D24: 9292 | E24: 7849 | F24: =E24+'Income Statement'!F20 -> 10627.499 | G24: =F24+'Income Statement'!G20 -> 13542.348 | H24: =G24+'Income Statement'!H20 -> 16601.285 | I24: =H24+'Income Statement'!I20 -> 19815.222 | J24: =I24+'Income Statement'!J20 -> 23195.692
A25: Total equity | B25: 20 | C25: =SUM(C23:C24) -> 3070622 | D25: =SUM(D23:D24) -> 3543238 | E25: =SUM(E23:E24) -> 3914742 | F25: =SUM(F23:F24) -> 4287277.4 | G25: =SUM(G23:G24) -> 4699149.7 | H25: =SUM(H23:H24) -> 5166229.9 | I25: =SUM(I23:I24) -> 5693335.6 | J25: =SUM(J23:J24) -> 6284886.6
A27: Employee benefits | B27: 22 | C27: 123045 | D27: 134147 | E27: 145294 | F27: =E27 -> 145294 | G27: =F27 -> 145294 | H27: =G27 -> 145294 | I27: =H27 -> 145294 | J27: =I27 -> 145294
A28: Provisions | B28: 23 | C28: 187276 | D28: 206212 | E28: 184481 | F28: =E28 -> 184481 | G28: =F28 -> 184481 | H28: =G28 -> 184481 | I28: =H28 -> 184481 | J28: =I28 -> 184481
A29: Deferred tax liabilities | B29: 10 | C29: 136846 | D29: 110016 | E29: 254387 | F29: =E29 -> 254387 | G29: =F29 -> 254387 | H29: =G29 -> 254387 | I29: =H29 -> 254387 | J29: =I29 -> 254387
A30: Debt | B30: 24 | C30: 2477186 | D30: 3351888 | E30: 2884220 | F30: =E30+Assumptions!F47-Assumptions!F40 -> 2884220 | G30: =F30+Assumptions!G47-Assumptions!G40 -> 2884220 | H30: =G30+Assumptions!H47-Assumptions!H40 -> 2884220 | I30: =H30+Assumptions!I47-Assumptions!I40 -> 2884220 | J30: =I30+Assumptions!J47-Assumptions!J40 -> 2884220
A31: Other liabilities | B31: 25 | C31: 1022967 | D31: 1106221 | E31: 1391616 | F31: =Assumptions!F61*Assumptions!F4 -> 1480076.3 | G31: =Assumptions!G61*Assumptions!G4 -> 1543978.8 | H31: =Assumptions!H61*Assumptions!H4 -> 1610640.3 | I31: =Assumptions!I61*Assumptions!I4 -> 1680179.9 | J31: =Assumptions!J61*Assumptions!J4 -> 1752721.9
A32: Other financial liabilities | B32: 19 | C32: 13539 | D32: 61894 | E32: 7405 | F32: =E32 -> 7405 | G32: =F32 -> 7405 | H32: =G32 -> 7405 | I32: =H32 -> 7405 | J32: =I32 -> 7405
A33: Trade payables | B33: 26 | C33: 930560 | D33: 945657 | E33: 841256 | F33: =Assumptions!F27 -> 894731.76 | G33: =Assumptions!G27 -> 933361.93 | H33: =Assumptions!H27 -> 973659.97 | I33: =Assumptions!I27 -> 1015697.9 | J33: =Assumptions!J27 -> 1059550.8
A34: Tax payables | C34: 89271 | D34: 37873 | E34: 4951 | F34: =E34 -> 4951 | G34: =F34 -> 4951 | H34: =G34 -> 4951 | I34: =H34 -> 4951 | J34: =I34 -> 4951
A35: Total Liabilities | C35: =SUM(C27:C34) -> 4980690 | D35: =SUM(D27:D34) -> 5953908 | E35: =SUM(E27:E34) -> 5713610 | F35: =SUM(F27:F34) -> 5855546 | G35: =SUM(G27:G34) -> 5958078.7 | H35: =SUM(H27:H34) -> 6065038.2 | I35: =SUM(I27:I34) -> 6176615.8 | J35: =SUM(J27:J34) -> 6293010.7
A37: Total equity and liabilities | C37: =C35+C25 -> 8051312 | D37: =D35+D25 -> 9497146 | E37: =E35+E25 -> 9628352 | F37: =F35+F25 -> 10142823 | G37: =G35+G25 -> 10657228 | H37: =H35+H25 -> 11231268 | I37: =I35+I25 -> 11869951 | J37: =J35+J25 -> 12577897
A39: Balance check | C39: =C37-C20 -> 0 | D39: =D37-D20 -> 0 | E39: =E37-E20 -> 0 | F39: =F37-F20 -> 0 | G39: =G37-G20 -> 0 | H39: =H37-H20 -> 0 | I39: =I37-I20 -> 0 | J39: =J37-J20 -> 0

Sheet Cash Flow Statement
B2: For the years ended December 31, | F2: Forecasted years
A3: (EUR thousand) | C3: 2023 | D3: 2024 | E3: 2025 | F3: 2026 | G3: 2027 | H3: 2028 | I3: 2029 | J3: 2030
A4: Cash and cash equivalents at the beginning of the year | C4: 1388901 | D4: =C48 -> 1121981 | E4: =D48 -> 1742214 | F4: ='Balance Sheet'!E18 -> 1467711 | G4: =F48 -> 1613413.4 | H4: =G48 -> 1828278 | I4: =H48 -> 2128381.5 | J4: =I48 -> 2519838.2
A5: Cash flows from operating activities:
A6: Net profit | C6: 1257457 | D6: 1525913 | E6: 1599516 | F6: ='Income Statement'!F17 -> 1711303 | G6: ='Income Statement'!G17 -> 1795282.1 | H6: ='Income Statement'!H17 -> 1884027.1 | I6: ='Income Statement'!I17 -> 1979493 | J6: ='Income Statement'!J17 -> 2082062.7
A7: Income tax expense | B7: 10 | C7: 344897 | D7: 363043 | E7: 464119 | F7: ='Income Statement'!F16 -> 511168.42 | G7: ='Income Statement'!G16 -> 536253.09 | H7: ='Income Statement'!H16 -> 562761.34 | I7: ='Income Statement'!I16 -> 591277.14 | J7: ='Income Statement'!J16 -> 621914.82
A8: Amortization and depreciation | B8: 14,15 | C8: 662305 | D8: 666777 | E8: 661936 | F8: =Assumptions!F32 -> 710600 | G8: =Assumptions!G32 -> 741280.26 | H8: =Assumptions!H32 -> 773285.13 | I8: =Assumptions!I32 -> 806671.83 | J8: =Assumptions!J32 -> 841500
A9: Provision accruals | B9: 23 | C9: 64834 | D9: 81546 | E9: 54466 | F9: 0 | G9: 0 | H9: 0 | I9: 0 | J9: 0
A10: Result from investments | B10: 16 | C10: -6137 | D10: -8245 | E10: -12572 | F10: =-'Income Statement'!F10 -> -12572 | G10: =-'Income Statement'!G10 -> -12572 | H10: =-'Income Statement'!H10 -> -12572 | I10: =-'Income Statement'!I10 -> -12572 | J10: =-'Income Statement'!J10 -> -12572
A11: Financial income | B11: 9 | C11: -132319 | D11: -147100 | E11: -168145 | F11: =-'Income Statement'!F12 -> -152202.17 | G11: =-'Income Statement'!G12 -> -164465.87 | H11: =-'Income Statement'!H12 -> -178739.63 | I11: =-'Income Statement'!I12 -> -197382.08 | J11: =-'Income Statement'!J12 -> -220702.08
A12: Financial expenses | B12: 9 | C12: 147334 | D12: 145895 | E12: 214226 | F12: ='Income Statement'!F13 -> 184336.38 | G12: ='Income Statement'!G13 -> 184336.38 | H12: ='Income Statement'!H13 -> 184336.38 | I12: ='Income Statement'!I13 -> 184336.38 | J12: ='Income Statement'!J13 -> 184336.38
A13: Other non-cash expenses, net | B13: 32 | C13: 79813 | D13: 91909 | E13: 98169 | F13: 0 | G13: 0 | H13: 0 | I13: 0 | J13: 0
A14: Change in inventories | B14: 17 | C14: -309564 | D14: -157526 | E14: -76684 | F14: =-('Balance Sheet'!F12-'Balance Sheet'!E12) -> -68672.556 | G14: =-('Balance Sheet'!G12-'Balance Sheet'!F12) -> -51057.91 | H14: =-('Balance Sheet'!H12-'Balance Sheet'!G12) -> -53262.342 | I14: =-('Balance Sheet'!I12-'Balance Sheet'!H12) -> -55561.951 | J14: =-('Balance Sheet'!J12-'Balance Sheet'!I12) -> -57960.846
A15: Change in trade receivables | B15: 18 | C15: -33381 | D15: -94029 | E15: -20617 | F15: =-('Balance Sheet'!F13-'Balance Sheet'!E13) -> -10809.6 | G15: =-('Balance Sheet'!G13-'Balance Sheet'!F13) -> -16024.393 | H15: =-('Balance Sheet'!H13-'Balance Sheet'!G13) -> -16716.249 | I15: =-('Balance Sheet'!I13-'Balance Sheet'!H13) -> -17437.975 | J15: =-('Balance Sheet'!J13-'Balance Sheet'!I13) -> -18190.862
A16: Change in trade payables | B16: 26 | C16: 43277 | D16: 7672 | E16: -59130 | F16: =('Balance Sheet'!F33-'Balance Sheet'!E33) -> 53475.763 | G16: =('Balance Sheet'!G33-'Balance Sheet'!F33) -> 38630.17 | H16: =('Balance Sheet'!H33-'Balance Sheet'!G33) -> 40298.033 | I16: =('Balance Sheet'!I33-'Balance Sheet'!H33) -> 42037.907 | J16: =('Balance Sheet'!J33-'Balance Sheet'!I33) -> 43852.899
A17: Change in receivables from financing activities | B17: 27 | C17: -107247 | D17: -118687 | E17: -154580 | F17: =-('Balance Sheet'!F14-'Balance Sheet'!E14) -> -102558.06 | G17: =-('Balance Sheet'!G14-'Balance Sheet'!F14) -> -74086.559 | H17: =-('Balance Sheet'!H14-'Balance Sheet'!G14) -> -77285.256 | I17: =-('Balance Sheet'!I14-'Balance Sheet'!H14) -> -80622.058 | J17: =-('Balance Sheet'!J14-'Balance Sheet'!I14) -> -84102.927
A18: Change in other operating assets and liabilities | C18: 48642 | D18: -20045 | E18: 222377 | F18: =-('Balance Sheet'!F16-'Balance Sheet'!E16)+('Balance Sheet'!F31-'Balance Sheet'!E31) -> 83703.543 | G18: =-('Balance Sheet'!G16-'Balance Sheet'!F16)+('Balance Sheet'!G31-'Balance Sheet'!F31) -> 56822.654 | H18: =-('Balance Sheet'!H16-'Balance Sheet'!G16)+('Balance Sheet'!H31-'Balance Sheet'!G31) -> 59275.98 | I18: =-('Balance Sheet'!I16-'Balance Sheet'!H16)+('Balance Sheet'!I31-'Balance Sheet'!H31) -> 61835.229 | J18: =-('Balance Sheet'!J16-'Balance Sheet'!I16)+('Balance Sheet'!J31-'Balance Sheet'!I31) -> 64504.974
A19: Finance income received | B19: 9 | C19: 32432 | D19: 49673 | E19: 38035 | F19: =-F11 -> 152202.17 | G19: =-G11 -> 164465.87 | H19: =-H11 -> 178739.63 | I19: =-I11 -> 197382.08 | J19: =-J11 -> 220702.08
A20: Finance costs paid | B20: 9 | C20: -83243 | D20: -50354 | E20: -126257 | F20: =-F12 -> -184336.38 | G20: =-G12 -> -184336.38 | H20: =-H12 -> -184336.38 | I20: =-I12 -> -184336.38 | J20: =-J12 -> -184336.38
A21: Income tax paid | B21: 10 | C21: -292463 | D21: -409786 | E21: -385554 | F21: =-F7 -> -511168.42 | G21: =-G7 -> -536253.09 | H21: =-H7 -> -562761.34 | I21: =-I7 -> -591277.14 | J21: =-J7 -> -621914.82
A22: Total cash flows from operating activities | C22: =SUM(C6:C21) -> 1716637 | D22: =SUM(D6:D21) -> 1926656 | E22: =SUM(E6:E21) -> 2349305 | F22: =SUM(F6:F21) -> 2364470 | G22: =SUM(G6:G21) -> 2478274.3 | H22: =SUM(H6:H21) -> 2597050.4 | I22: =SUM(I6:I21) -> 2723844 | J22: =SUM(J6:J21) -> 2859093.9
A24: Cash flows used in investing activities:
A25: Investments in intangible assets | B25: 14 | C25: -487148 | D25: -506874 | E25: -457976 | F25: =-Assumptions!F34*Assumptions!F31 -> -427295.23 | G25: =-Assumptions!G34*Assumptions!G31 -> -427295.23 | H25: =-Assumptions!H34*Assumptions!H31 -> -427295.23 | I25: =-Assumptions!I34*Assumptions!I31 -> -427295.23 | J25: =-Assumptions!J34*Assumptions!J31 -> -427295.23
A26: Investments in property, plant and equipment | B26: 15 | C26: -381762 | D26: -482277 | E26: -485210 | F26: =-Assumptions!F35*Assumptions!F31 -> -452704.77 | G26: =-Assumptions!G35*Assumptions!G31 -> -452704.77 | H26: =-Assumptions!H35*Assumptions!H31 -> -452704.77 | I26: =-Assumptions!I35*Assumptions!I31 -> -452704.77 | J26: =-Assumptions!J35*Assumptions!J31 -> -452704.77
A27: Acquisition of subsidiary and other investments | C27: 0 | D27: 0 | E27: -1352 | F27: 0 | G27: 0 | H27: 0 | I27: 0 | J27: 0
A28: Proceeds from the sale of property, plant and equipment and intangible assets | B28: 14,15 | C28: 2458 | D28: 2041 | E28: 400 | F28: 0 | G28: 0 | H28: 0 | I28: 0 | J28: 0
A29: Total cash flows used in investing activities | C29: =SUM(C25:C28) -> -866452 | D29: =SUM(D25:D28) -> -987110 | E29: =SUM(E25:E28) -> -944138 | F29: =SUM(F25:F28) -> -880000 | G29: =SUM(G25:G28) -> -880000 | H29: =SUM(H25:H28) -> -880000 | I29: =SUM(I25:I28) -> -880000 | J29: =SUM(J25:J28) -> -880000
A31: Cash flows used in financing activities:
A32: Repayments of bonds and notes | B32: 24 | C32: -575702 | D32: 0 | E32: -450963 | F32: =-Assumptions!F40*Assumptions!F42 -> -471520.76 | G32: =-Assumptions!G40*Assumptions!G42 -> -393195.85 | H32: =-Assumptions!H40*Assumptions!H42 -> -393195.85 | I32: =-Assumptions!I40*Assumptions!I42 -> -393195.85 | J32: =-Assumptions!J40*Assumptions!J42 -> -393195.85
A33: Proceeds from bonds and notes | B33: 24 | C33: 0 | D33: 496145 | E33: 0 | F33: =Assumptions!F49*Assumptions!F47 -> 223797.25 | G33: =Assumptions!G49*Assumptions!G47 -> 186622 | H33: =Assumptions!H49*Assumptions!H47 -> 186622 | I33: =Assumptions!I49*Assumptions!I47 -> 186622 | J33: =Assumptions!J49*Assumptions!J47 -> 186622
A34: Repayments of securitizations | B34: 24 | C34: -49611 | D34: -243649 | E34: -33294 | F34: =-Assumptions!F40*Assumptions!F43 -> -149977.83 | G34: =-Assumptions!G40*Assumptions!G43 -> -125064.83 | H34: =-Assumptions!H40*Assumptions!H43 -> -125064.83 | I34: =-Assumptions!I40*Assumptions!I43 -> -125064.83 | J34: =-Assumptions!J40*Assumptions!J43 -> -125064.83
A35: Proceeds from securitizations | B35: 24 | C35: 151217 | D35: 340499 | E35: 142375 | F35: =Assumptions!F50*Assumptions!F47 -> 286020.86 | G35: =Assumptions!G50*Assumptions!G47 -> 238509.58 | H35: =Assumptions!H50*Assumptions!H47 -> 238509.58 | I35: =Assumptions!I50*Assumptions!I47 -> 238509.58 | J35: =Assumptions!J50*Assumptions!J47 -> 238509.58
A36: Repayments of borrowings from banks and other financial institutions | B36: 24 | C36: -72500 | D36: -104690 | E36: -378332 | F36: =-Assumptions!F40*Assumptions!F44 -> -255136.93 | G36: =-Assumptions!G40*Assumptions!G44 -> -212755.81 | H36: =-Assumptions!H40*Assumptions!H44 -> -212755.81 | I36: =-Assumptions!I40*Assumptions!I44 -> -212755.81 | J36: =-Assumptions!J40*Assumptions!J44 -> -212755.81
A37: Proceeds from borrowings from banks and other financial institutions | B37: 24 | C37: 250000 | D37: 225000 | E37: 400000 | F37: =Assumptions!F51*Assumptions!F47 -> 394688.23 | G37: =Assumptions!G51*Assumptions!G47 -> 329126.07 | H37: =Assumptions!H51*Assumptions!H47 -> 329126.07 | I37: =Assumptions!I51*Assumptions!I47 -> 329126.07 | J37: =Assumptions!J51*Assumptions!J47 -> 329126.07
A38: Repayments of other debt | B38: 24 | C38: -35566 | D38: -41297 | E38: -46161 | F38: =-Assumptions!F40*Assumptions!F45 -> -56501.751 | G38: =-Assumptions!G40*Assumptions!G45 -> -47116.174 | H38: =-Assumptions!H40*Assumptions!H45 -> -47116.174 | I38: =-Assumptions!I40*Assumptions!I45 -> -47116.174 | J38: =-Assumptions!J40*Assumptions!J45 -> -47116.174
A39: Proceeds from other debt | B39: 24 | C39: 34596 | D39: 51022 | E39: 42527 | F39: =Assumptions!F52*Assumptions!F47 -> 57802.655 | G39: =Assumptions!G52*Assumptions!G47 -> 48200.983 | H39: =Assumptions!H52*Assumptions!H47 -> 48200.983 | I39: =Assumptions!I52*Assumptions!I47 -> 48200.983 | J39: =Assumptions!J52*Assumptions!J47 -> 48200.983
A40: Repayments of lease liabilities | B40: 24 | C40: -17691 | D40: -22001 | E40: -23825 | F40: =-Assumptions!F40*Assumptions!F46 -> -29171.72 | G40: =-Assumptions!G40*Assumptions!G46 -> -24325.969 | H40: =-Assumptions!H40*Assumptions!H46 -> -24325.969 | I40: =-Assumptions!I40*Assumptions!I46 -> -24325.969 | J40: =-Assumptions!J40*Assumptions!J46 -> -24325.969
A41: Dividends paid to owners of the parent | B41: 20 | C41: -328631 | D41: -439918 | E41: -529707 | F41: =-Assumptions!F57*'Income Statement'!E19 -> -638767.6 | G41: =-Assumptions!G57*'Income Statement'!F19 -> -683409.78 | H41: =-Assumptions!H57*'Income Statement'!G19 -> -716946.9 | I41: =-Assumptions!I57*'Income Statement'!H19 -> -752387.26 | J41: =-Assumptions!J57*'Income Statement'!I19 -> -790511.63
A42: Dividends paid to non-controlling interests | B42: 20 | C42: -4890 | D42: -4788 | E42: -4448 | F42: 0 | G42: 0 | H42: 0 | I42: 0 | J42: 0
A43: Share repurchases | B43: 20 | C43: -460629 | D43: -581084 | E43: -785329 | F43: =-Assumptions!F58 -> -700000 | G43: =-Assumptions!G58 -> -700000 | H43: =-Assumptions!H58 -> -700000 | I43: =-Assumptions!I58 -> -700000 | J43: =-Assumptions!J58 -> -700000
...

Sheet EPS
B2: 2023 | C2: 2024 | D2: 2025 | E2: 2026 | F2: 2027 | G2: 2028 | H2: 2029 | I2: 2030
A3: Profit attributable to owners of the Company (thousand euros) | B3: 1252048 | C3: 1521877 | D3: 1596919 | E3: ='Income Statement'!F19 -> 1708524.5 | F3: ='Income Statement'!G19 -> 1792367.3 | G3: ='Income Statement'!H19 -> 1880968.2 | H3: ='Income Statement'!I19 -> 1976279.1 | I3: ='Income Statement'!J19 -> 2078682.2
A4: Weighted average number of common shares for diluted earnings per common share (thousand) | B4: 181511 | C4: 179992 | D4: 178321 | E4: =E12 -> 176717.56 | F4: =F12 -> 175128.56 | G4: =G12 -> 173553.87 | H4: =H12 -> 171993.34 | I4: =I12 -> 170446.87
A5: Diluted earnings per common share (euros) | B5: =B3/B4 -> 6.897918 | C5: =C3/C4 -> 8.455248 | D5: =D3/D4 -> 8.9553053 | E5: =E3/E4 -> 9.6681077 | F5: =F3/F4 -> 10.23458 | G5: =G3/G4 -> 10.83795 | H5: =H3/H4 -> 11.490439 | I5: =I3/I4 -> 12.195485
A8: Number o/ shares | B8: 2023 | C8: 2024 | D8: 2025 | E8: 2026 | F8: 2027 | G8: 2028 | H8: 2029 | I8: 2030
A9: Weighted average number of common shares for basic earnings per share | B9: 181220 | C9: 179743 | D9: 178125 | E9: =D9*(1+Assumptions!E62) -> 176521.56 | F9: =E9*(1+Assumptions!F62) -> 174932.56 | G9: =F9*(1+Assumptions!G62) -> 173357.87 | H9: =G9*(1+Assumptions!H62) -> 171797.34 | I9: =H9*(1+Assumptions!I62) -> 170250.87
A10: Adjustments for calculation of diluted earnings per share:
A11: Share-based compensation | B11: 291 | C11: 249 | D11: 196 | E11: 196 | F11: 196 | G11: 196 | H11: 196 | I11: 196
A12: Weighted average number of common shares for diluted earnings per share | B12: =B11+B9 -> 181511 | C12: =C11+C9 -> 179992 | D12: =D11+D9 -> 178321 | E12: =E11+E9 -> 176717.56 | F12: =F11+F9 -> 175128.56 | G12: =G11+G9 -> 173553.87 | H12: =H11+H9 -> 171993.34 | I12: =I11+I9 -> 170446.87
A13: Basic earnings per common share (in €) | B13: =B3/B9 -> 6.9089946 | C13: =C3/C9 -> 8.4669612 | D13: =D3/D9 -> 8.9651593 | E13: =E3/E9 -> 9.6788427 | F13: =F3/F9 -> 10.246047 | G13: =G3/G9 -> 10.850204 | H13: =H3/H9 -> 11.503549 | I13: =I3/I9 -> 12.209525

Sheet Debt
B3: At December 31,
B4: 2024 | E4: 2025
B5: Current | C5: Non-current | D5: Total | E5: Current | F5: Non-current | G5: Total
B6: (EUR thousand)
A7: Asset-backed financing (Securitizations) | B7: 649173 | C7: 693082 | D7: 1342255 | E7: 669185 | F7: 619205 | G7: 1288390
A8: Bonds and notes | B8: 459056 | C8: 953917 | D8: 1412973 | E8: 12368 | F8: 946907 | G8: 959275
A9: Borrowings from banks and other financial institutions | B9: 143800 | C9: 270833 | D9: 414633 | E9: 203021 | F9: 225000 | G9: 428021
A10: Lease liabilities | B10: 26491 | C10: 99779 | D10: 126270 | E10: 31348 | F10: 130799 | G10: 162147
A11: Other debt | B11: 55757 | C11: 0 | D11: 55757 | E11: 46387 | F11: 0 | G11: 46387
A12: Total debt | B12: =SUM(B7:B11) -> 1334277 | C12: =SUM(C7:C11) -> 2017611 | D12: =SUM(D7:D11) -> 3351888 | E12: =SUM(E7:E11) -> 962309 | F12: =SUM(F7:F11) -> 1921911 | G12: =SUM(G7:G11) -> 2884220

Sheet PPE and Intangible
A3: Intangible Assets (EUR thousand)
B4: 2023 | C4: 2024 | D4: 2025
A5: Additions | B5: 487148 | C5: 506874 | D5: 457976
A6: Amortization | B6: 372101 | C6: 367139 | D6: 363202
A8: PPE | B8: 2023 | C8: 2024 | D8: 2025
A9: Additions | B9: 423815 | C9: 556956 | D9: 554916
A10: Depreciation | B10: 290204 | C10: 299638 | D10: 298734
A12: Both
A13: Total additions | B13: =B9+B5 -> 910963 | C13: =C9+C5 -> 1063830 | D13: =D9+D5 -> 1012892
A14: Total D&A | B14: =B10+B6 -> 662305 | C14: =C10+C6 -> 666777 | D14: =D10+D6 -> 661936

Sheet Income tax
C3: For the years ended December 31,
B4: 2023 | C4: 2024 | D4: 2025
B5: (EUR thousand)
A6: Current tax expense | B6: 347162 | C6: 383481 | D6: 360443
A7: Deferred tax expense/(benefit) | B7: -4541 | C7: -17483 | D7: 106556
A8: Taxes relating to prior years | B8: 2276 | C8: -2955 | D8: -2880
A9: Total income tax expense | B9: =SUM(B6:B8) -> 344897 | C9: =SUM(C6:C8) -> 363043 | D9: =SUM(D6:D8) -> 464119

Sheet full ppe
A1: Movements in property, plant and equipment are summarized below.
B2: Land | C2: Industrial buildings | D2: Plant, machinery and equipment | E2: Other assets | F2: Advances and assets under construction | G2: Total
A3: (€ thousand)
A4: Gross carrying amount at December 31, 2023 | B4: 151229 | C4: 523147 | D4: 3205733 | E4: 265245 | F4: 391792 | G4: 4537146
A5: Additions | B5: 1565 | C5: 56504 | D5: 105175 | E5: 60804 | F5: 332908 | G5: 556956
A6: Divestitures | B6: — | C6: -2853 | D6: -75491 | E6: -7039 | F6: -78 | G6: -85461
A7: Reclassifications | B7: 1 | C7: 80119 | D7: 116426 | E7: -6600 | F7: -224842 | G7: -34896
A8: Translation differences and other movements | B8: 18 | C8: 509 | D8: -1848 | E8: 4459 | F8: -645 | G8: 2493
A9: Balance at December 31, 2024 | B9: 152813 | C9: 657426 | D9: 3349995 | E9: 316869 | F9: 499135 | G9: 4976238
A10: Additions | B10: — | C10: 27029 | D10: 159208 | E10: 80565 | F10: 288114 | G10: 554916
A11: Divestitures | B11: — | C11: -2595 | D11: -72851 | E11: -20028 | F11: -1198 | G11: -96672
A12: Reclassifications | B12: 5353 | C12: 14452 | D12: 244518 | E12: -3925 | F12: -272519 | G12: -12121
A13: Translation differences and other movements | B13: -34 | C13: -3065 | D13: -86 | E13: -7584 | F13: -10089 | G13: -20858
A14: Balance at December 31, 2025 | B14: 158132 | C14: 693247 | D14: 3680784 | E14: 365897 | F14: 503443 | G14: 5401503
A16: Accumulated depreciation at December 31, 2023 | B16: — | C16: 232068 | D16: 2547621 | E16: 182257 | F16: — | G16: 2961946
A17: Depreciation | B17: — | C17: 27042 | D17: 243424 | E17: 29172 | F17: — | G17: 299638
A18: Divestitures | B18: — | C18: -1516 | D18: -72308 | E18: -6540 | F18: — | G18: -80364
A19: Reclassifications | B19: — | C19: -8153 | D19: -12355 | E19: -12668 | F19: — | G19: -33176
A20: Translation differences and other movements | B20: — | C20: -56 | D20: -4226 | E20: 3692 | F20: — | G20: -590
A21: Balance at December 31, 2024 | B21: — | C21: 249385 | D21: 2702156 | E21: 195913 | F21: — | G21: 3147454
A22: Depreciation | B22: — | C22: 30017 | D22: 234243 | E22: 34474 | F22: — | G22: 298734
A23: Divestitures | B23: — | C23: -1693 | D23: -70264 | E23: -17403 | F23: — | G23: -89360
A24: Reclassifications | B24: — | C24: -5170 | D24: -516 | E24: -5053 | F24: — | G24: -10739
A25: Translation differences and other movements | B25: — | C25: -1694 | D25: 1745 | E25: -2528 | F25: — | G25: -2477
A26: Balance at December 31, 2025 | B26: — | C26: 270845 | D26: 2867364 | E26: 205403 | F26: — | G26: 3343612
A28: Carrying amount at:
A29: December 31, 2023 | B29: 151229 | C29: 291079 | D29: 658112 | E29: 82988 | F29: 391792 | G29: 1575200
A30: o/ which right-o/ use assets under IFRS 16 | B30: — | C30: 22971 | D30: 3396 | E30: 41888 | F30: — | G30: 68255
A31: December 31, 2024 | B31: 152813 | C31: 408041 | D31: 647839 | E31: 120956 | F31: 499135 | G31: 1828784
A32: o/ which right-o/ use assets under IFRS 16 | B32: — | C32: 38918 | D32: 8569 | E32: 68884 | F32: — | G32: 116371
A33: December 31, 2025 | B33: 158132 | C33: 422402 | D33: 813420 | E33: 160494 | F33: 503443 | G33: 2057891
A34: o/ which right-o/ use assets under IFRS 16 | B34: — | C34: 37022 | D34: 6131 | E34: 103113 | F34: — | G34: 146266

Sheet ia full
A1: INTANGIBLE ASSETS
A2: Movements in intangible assets are summarized below.
B3: Externally acquired development costs | C3: Development costs internally generated | D3: Patents, concessions and lis9ns9s | E3: Other intangible assets | F3: Total
A4: (EUR thousand)
A5: Gross carrying amount at December 31, 2023 | B5: 2607792 | C5: 1188371 | D5: 318585 | E5: 67788 | F5: 4182536
A6: Additions | B6: 306559 | C6: 169908 | D6: 26453 | E6: 3954 | F6: 506874
A7: Divestitures | B7: -14632 | C7: -945 | D7: -1613 | E7: -12 | F7: -17202
A8: Reclassifications | B8: — | C8: — | D8: 10267 | E8: -9684 | F8: 583
A9: Translation differences and other movements | B9: 2633 | C9: -2632 | D9: — | E9: -15000 | F9: -14999
A10: Balance at December 31, 2024 | B10: 2902352 | C10: 1354702 | D10: 353692 | E10: 47046 | F10: 4657792
A11: Additions | B11: 248733 | C11: 172532 | D11: 32846 | E11: 3865 | F11: 457976
A12: Divestitures | B12: -1949 | C12: -498 | D12: -1541 | E12: -17 | F12: -4005
A13: Reclassifications | B13: — | C13: — | D13: 1814 | E13: -340 | F13: 1474
A14: Translation differences and other movements | B14: — | C14: — | D14: -2 | E14: -25 | F14: -27
A15: Balance at December 31, 2025 | B15: 3149136 | C15: 1526736 | D15: 386809 | E15: 50529 | F15: 5113210
A17: Accumulated amortization at December 31, 2023 | B17: 1760157 | C17: 666111 | D17: 282628 | E17: 53941 | F17: 2762837
A18: Amortization | B18: 237414 | C18: 93367 | D18: 34695 | E18: 1663 | F18: 367139
A19: Divestitures | B19: -2881 | C19: — | D19: — | E19: — | F19: -2881
A20: Reclassification | B20: — | C20: — | D20: 31 | E20: — | F20: 31
A21: Translation differences and other movements | B21: — | C21: -3 | D21: — | E21: -14995 | F21: -14998
A22: Balance at December 31, 2024 | B22: 1994690 | C22: 759475 | D22: 317354 | E22: 40609 | F22: 3112128
A23: Amortization | B23: 219282 | C23: 106889 | D23: 34821 | E23: 2210 | F23: 363202
A24: Divestitures | B24: -247 | C24: — | D24: -644 | E24: — | F24: -891
A25: Reclassification | B25: — | C25: — | D25: 314 | E25: — | F25: 314
A26: Balance at December 31, 2025 | B26: 2213725 | C26: 866364 | D26: 351845 | E26: 42819 | F26: 3474753
A28: Carrying amount at:
A29: December 31, 2023 | B29: 847635 | C29: 522260 | D29: 35957 | E29: 13847 | F29: 1419699
A30: December 31, 2024 | B30: 907662 | C30: 595227 | D30: 36338 | E30: 6437 | F30: 1545664
A31: December 31, 2025 | B31: 935411 | C31: 660372 | D31: 34964 | E31: 7710 | F31: 1638457
